Workbook

Sheet TABLA_ORIGINAL
A1: Región | B1: PA | C1: Nombre | D1: Provincia | E1: Distrito | F1: Corregimiento | G1: Tipo UM | H1: Latitud | I1: Longitud | J1: Fecha de Activación
A2: 1 | B2: 1 | C2: Colegio Rogelio Josué Ibarra | D2: Bocas del Toro | E2: Bocas del Toro | F2: Bocas del Toro | G2: FO | H2: 9.340654 | I2: -82.242499 | J2: 12/07/2017
A3: 1 | B3: 3 | C3: Escuela República de Nicaragua | D3: Bocas del Toro | E3: Bocas del Toro | F3: Bocas del Toro | G3: FO | H3: 9.338938 | I3: -82.242668 | J3: 12/07/2017
A4: 1 | B4: 6 | C4: Col. Sec. de Almirante | D4: Bocas del Toro | E4: Almirante | F4: Puerto Almirante | G4: FO | H4: 9.299741 | I4: -82.413301 | J4: 10/07/2017
A5: 1 | B5: 7 | C5: Escuela Almirante | D5: Bocas del Toro | E5: Almirante | F5: Puerto Almirante | G5: FO | H5: 9.292715 | I5: -82.394887 | J5: 28/06/2017
A6: 1 | B6: 8 | C6: Escuela Barriada Guaymi | D6: Bocas del Toro | E6: Almirante | F6: Puerto Almirante | G6: FO | H6: 9.290074 | I6: -82.4044 | J6: 30/06/2017
A7: 1 | B7: 9 | C7: Escuela Berta López | D7: Bocas del Toro | E7: Almirante | F7: Puerto Almirante | G7: FO | H7: 9.29509 | I7: -82.404895 | J7: 29/06/2017
A8: 1 | B8: 10 | C8: Escuela Miraflores | D8: Bocas del Toro | E8: Almirante | F8: Puerto Almirante | G8: FO | H8: 9.305504 | I8: -82.437321 | J8: 10/07/2017
A9: 1 | B9: 11 | C9: Escuela Nuevo Paraíso | D9: Bocas del Toro | E9: Almirante | F9: Puerto Almirante | G9: FO | H9: 9.283946 | I9: -82.410794 | J9: 29/06/2017
A10: 1 | B10: 13 | C10: BDA | D10: Bocas del Toro | E10: Changuinola | F10: Changuinola | G10: FO | H10: 9.437215 | I10: -82.519311 | J10: 10/07/2017
A11: 1 | B11: 17 | C11: Escuela Finca 41 | D11: Bocas del Toro | E11: Changuinola | F11: Changuinola | G11: FO | H11: 9.471103 | I11: -82.513954 | J11: 27/06/2017
A12: 1 | B12: 19 | C12: Hospital Changuinola | D12: Bocas del Toro | E12: Changuinola | F12: Changuinola | G12: FO | H12: 9.449043 | I12: -82.516495 | J12: 29/06/2017
A13: 1 | B13: 20 | C13: Instituto Profesional y técnico de Bocas del Toro | D13: Bocas del Toro | E13: Changuinola | F13: Changuinola | G13: HFC | H13: 9.47141 | I13: -82.51574 | J13: 26/06/2017
... A105: 1 | B105: 122 | C105: Centro de Salud Cerro Punta | D105: Chiriquí | E105: Tierras Altas | F105: Cerro Punta | G105: FO | H105: 8.853529 | I105: -82.574 | J105: 31/05/2017
A106: 1 | B106: 123 | C106: Esc. Guadalupe/Fernando Eleta Almarán | D106: Chiriquí | E106: Bugaba | G106: FO | H106: 8.869177 | I106: -82.567344 | J106: 31/05/2017
A107: 1 | B107: 124 | C107: Esc. Nueva Suiza | D107: Chiriquí | E107: Tierras Altas | F107: Cerro Punta | G107: FO | H107: 8.792701 | I107: -82.628149 | J107: 27/07/2017
A108: 1 | B108: 125 | C108: Esc. Gómez | D108: Chiriquí | E108: Bugaba | F108: Gómez | G108: FO | H108: 8.562305 | I108: -82.740249 | J108: 20/06/2017
A109: 1 | B109: 126 | C109: Esc. San Miguel de Exquisito | D109: Chiriquí | E109: Bugaba | F109: Gómez | G109: FO | H109: 8.550083 | I109: -82.757749 | J109: 14/07/2017
A110: 1 | B110: 128 | C110: Biblioteca Catolica | D110: Chiriquí | E110: Bugaba | F110: La Concepción | G110: FO | H110: 8.516109 | I110: -82.623139 | J110: 18/05/2017
A111: 1 | B111: 129 | C111: Biblioteca Pública La Concepción CENTRO ACP | D111: Chiriquí | E111: Bugaba | F111: La Concepción | G111: FO | H111: 8.517397 | I111: -82.618121 | J111: 18/05/2017
A112: 1 | B112: 131 | C112: Centro Cristiano Bugaba | D112: Chiriquí | E112: Bugaba | F112: La Concepción | G112: FO | H112: 8.518749 | I112: -82.621191 | J112: 24/05/2017
A113: 1 | B113: 132 | C113: Esc. Cuesta de Piedra | D113: Chiriquí | E113: Bugaba | F113: La Concepción | G113: FO | H113: 8.677318 | I113: -82.624258 | J113: 27/07/2017
A114: 1 | B114: 133 | C114: Esc. de Solano | D114: Chiriquí | E114: Bugaba | F114: La Concepción | G114: FO | H114: 8.5158 | I114: -82.611886 | J114: 24/05/2017
A115: 1 | B115: 134 | C115: Esc. San Vicente | D115: Chiriquí | E115: Bugaba | F115: La Concepción | G115: FO | H115: 8.592583 | I115: -82.636638 | J115: 27/07/2017
A116: 1 | B116: 135 | C116: Escuela Belen | D116: Chiriquí | E116: Bugaba | F116: La Concepción | G116: FO | H116: 8.515317 | I116: -82.628042 | J116: 24/05/2017
A117: 1 | B117: 136 | C117: Escuela Daniel Octavio Crespo | D117: Chiriquí | E117: Bugaba | F117: La Concepción | G117: FO | H117: 8.520229 | I117: -82.627342 | J117: 18/05/2017
A118: 1 | B118: 137 | C118: I.P.T. Solano | D118: Chiriquí | E118: Bugaba | F118: La Concepción | G118: HFC | H118: 8.520659 | I118: -82.613268 | J118: 25/05/2017
... A132: 1 | B132: 154 | C132: Bomberos Volcán | D132: Chiriquí | E132: Tierras Altas | F132: Volcán | G132: FO | H132: 8.77505 | I132: -82.639017 | J132: 31/05/2017
A133: 1 | B133: 155 | C133: C.E.B.G. de Volcán | D133: Chiriquí | E133: Bugaba | G133: FO | H133: 8.775136 | I133: -82.639093 | J133: 31/05/2017
A134: 1 | B134: 156 | C134: Esc. El Bijao | D134: Chiriquí | E134: Bugaba | G134: FO | H134: 8.709527 | I134: -82.624415 | J134: 27/07/2017
A135: 1 | B135: 157 | C135: Esc. El Valle. | D135: Chiriquí | E135: Tierras Altas | F135: Volcán | G135: HFC | H135: 8.77267 | I135: -82.649088 | J135: 01/06/2017
A136: 1 | B136: 158 | C136: Esc. Las Perlas | D136: Chiriquí | E136: Tierras Altas | F136: Volcán | G136: HFC | H136: 8.793414 | I136: -82.646085 | J136: 31/05/2017
A137: 1 | B137: 159 | C137: Parque Plaza Volcán | D137: Chiriquí | E137: Bugaba | F137: Volcán | G137: FO | H137: 8.777953 | I137: -82.643329 | J137: 01/06/2017
A138: 1 | B138: 160 | C138: Policía Nacional | D138: Chiriquí | E138: Bugaba | G138: FO | H138: 8.776175 | I138: -82.640403 | J138: 31/05/2017
A139: 1 | B139: 161 | C139: Esc. Chiriquí | D139: Chiriquí | E139: David | F139: Chiriquí | G139: FO | H139: 8.397895 | I139: -82.324775 | J139: 25/05/2017
A140: 1 | B140: 162 | C140: Esc. Chorcha Abajo | D140: Chiriquí | E140: David | F140: Chiriquí | G140: Satelital | H140: 8.370429 | I140: -82.279748 | J140: 16/10/2017
A141: 1 | B141: 163 | C141: Esc. El Veladero. | D141: Chiriquí | E141: David | F141: Chiriquí | G141: FO | H141: 8.432535 | I141: -82.287988 | J141: 25/05/2017
A142: 1 | B142: 164 | C142: Esc. La Pita | D142: Chiriquí | E142: David | F142: Chiriquí | G142: FO | H142: 8.399806 | I142: -82.25136 | J142: 25/05/2017
A143: 1 | B143: 165 | C143: Esc. Cochea Arriba | D143: Chiriquí | E143: David | F143: Cochea | G143: FO | H143: 8.542861 | I143: -82.378026 | J143: 16/10/2017
A144: 1 | B144: 166 | C144: Aldeas Infantiles SOS | D144: Chiriquí | E144: David | F144: San José de David | G144: FO | H144: 8.408425 | I144: -82.43341 | J144: 23/05/2017
...

Sheet TABLA_GRÁFICA_DINÁMICO
A1: Etiquetas de fila | B1: Cuenta de Región
A2: Aguadulce | B2: 30
A3: Alanje | B3: 7
A4: Almirante | B4: 6
A5: Antón | B5: 26
A6: Arraiján | B6: 43
A7: Atalaya | B7: 3
A8: Barú | B8: 38
A9: Besikó | B9: 1
A10: Bocas del Toro | B10: 6
A11: Boquerón | B11: 8
A12: Boquete | B12: 7
A13: Bugaba | B13: 45
... A79: Total general | B79: 1321

Sheet BD_PUNTOS_DE_ACCESO
A1: Región | B1: PA | C1: Nombre | D1: Provincia | E1: Distrito | F1: Corregimiento | G1: Tipo UM | H1: Latitud | I1: Longitud | J1: Fecha de Activación | K1: Proveedores | L1: Sesiones | M1: Total GB | N1: Nombre_Meduca | O1: Dependencia | P1: Status | Q1: Área | R1: Indígena | S1: Áreas Comarcales | T1: Decretos | U1: Muestra_Meduca
A2: 1 | B2: 64 | C2: Esc. La Esperanza | D2: Chiriquí | E2: Barú | F2: Baco | G2: FO | H2: 8.406897 | I2: -82.790057 | J2: 30/05/2017 | K2: =VLOOKUP(C2,BD_SESIONES_DE_USUARIO!A2:H61,7,FALSE) -> C&W Panamá | L2: =VLOOKUP(C2,BD_SESIONES_DE_USUARIO!A2:H61,5,FALSE) -> 1344 | M2: =VLOOKUP(C2,BD_DATA_TRANSFERIDA!A2:G61,5,FALSE) -> 74 | N2: C.E.B.G. LA ESPERANZA | P2: =VLOOKUP(N2,BD_MEDUCA!$A$4583:$M$4587,4,TRUE) -> CULTURA Y DEPORTE | Q2: =VLOOKUP(N2,BD_MEDUCA!$A$4583:$M$4587,10,TRUE) -> URBANA | R2: =VLOOKUP(N2,BD_MEDUCA!$A$4583:$M$4587,11,TRUE) -> NO | S2: =VLOOKUP(N2,BD_MEDUCA!$A$4583:$M$4587,12,TRUE) -> No | U2: =VLOOKUP(N2,BD_MEDUCA!$A$4583:$M$4587,2,TRUE) -> SUBSISTEMA REGULAR
A3: 1 | B3: 65 | C3: Esc. San Valentín | D3: Chiriquí | E3: Barú | F3: Baco | G3: FO | H3: 8.365272 | I3: -82.783435 | J3: 30/05/2017 | K3: =VLOOKUP(C3,BD_SESIONES_DE_USUARIO!A3:H62,7,FALSE) -> C&W Panamá | L3: =VLOOKUP(C3,BD_SESIONES_DE_USUARIO!A3:H62,5,FALSE) -> 2053 | M3: =VLOOKUP(C3,BD_DATA_TRANSFERIDA!A3:G62,5,FALSE) -> 124 | N3: C.E.B.G. SAN VALENTIN | O3: =VLOOKUP(N3,BD_MEDUCA!$A$4583:$M$4587,3,TRUE) -> OFICIAL | P3: =VLOOKUP(N3,BD_MEDUCA!$A$4583:$M$4587,4,TRUE) -> CULTURA Y DEPORTE | Q3: =VLOOKUP(N3,BD_MEDUCA!$A$4583:$M$4587,10,TRUE) -> URBANA | R3: =VLOOKUP(N3,BD_MEDUCA!$A$4583:$M$4587,11,TRUE) -> NO | S3: =VLOOKUP(N3,BD_MEDUCA!$A$4583:$M$4587,12,TRUE) -> No | T3: =VLOOKUP(N3,BD_MEDUCA!$A$4583:$M$4587,13,TRUE) -> NO ESPECIFICADO | U3: =VLOOKUP(N3,BD_MEDUCA!$A$4583:$M$4587,2,TRUE) -> SUBSISTEMA REGULAR
A4: 1 | B4: 66 | C4: Centro de Educ. Media de Progreso | D4: Chiriquí | E4: Barú | F4: Progreso | G4: PTP | H4: 8.451565 | I4: -82.834551 | J4: 25/07/2017 | K4: =VLOOKUP(C4,BD_SESIONES_DE_USUARIO!A4:H63,7,FALSE) -> C&W Panamá | L4: =VLOOKUP(C4,BD_SESIONES_DE_USUARIO!A4:H63,5,FALSE) -> 1633 | M4: =VLOOKUP(C4,BD_DATA_TRANSFERIDA!A4:G63,5,FALSE) -> 46 | N4: CENTRO EDUCATIVO DE PROGRESO | O4: =VLOOKUP(N4,BD_MEDUCA!$A$4583:$M$4587,3,TRUE) -> OFICIAL | P4: =VLOOKUP(N4,BD_MEDUCA!$A$4583:$M$4587,4,TRUE) -> CULTURA Y DEPORTE | Q4: =VLOOKUP(N4,BD_MEDUCA!$A$4583:$M$4587,10,TRUE) -> URBANA | R4: =VLOOKUP(N4,BD_MEDUCA!$A$4583:$M$4587,11,TRUE) -> NO | S4: =VLOOKUP(N4,BD_MEDUCA!$A$4583:$M$4587,12,TRUE) -> No | T4: =VLOOKUP(N4,BD_MEDUCA!$A$4583:$M$4587,13,TRUE) -> NO ESPECIFICADO | U4: =VLOOKUP(N4,BD_MEDUCA!$A$4583:$M$4587,2,TRUE) -> SUBSISTEMA REGULAR
A5: 1 | B5: 68 | C5: Esc. Chuchupate | D5: Chiriquí | E5: Barú | F5: Progreso | G5: PTP | H5: 8.347334 | I5: -82.801157 | J5: 25/07/2017 | K5: =VLOOKUP(C5,BD_SESIONES_DE_USUARIO!A5:H64,7,FALSE) -> C&W Panamá | L5: =VLOOKUP(C5,BD_SESIONES_DE_USUARIO!A5:H64,5,FALSE) -> 2114 | M5: =VLOOKUP(C5,BD_DATA_TRANSFERIDA!A5:G64,5,FALSE) -> 191 | N5: ESC. CHUCHUPATE | O5: =VLOOKUP(N5,BD_MEDUCA!$A$4583:$M$4587,3,TRUE) -> OFICIAL | P5: =VLOOKUP(N5,BD_MEDUCA!$A$4583:$M$4587,4,TRUE) -> CULTURA Y DEPORTE | Q5: =VLOOKUP(N5,BD_MEDUCA!$A$4583:$M$4587,10,TRUE) -> URBANA | R5: =VLOOKUP(N5,BD_MEDUCA!$A$4583:$M$4587,11,TRUE) -> NO | S5: =VLOOKUP(N5,BD_MEDUCA!$A$4583:$M$4587,12,TRUE) -> No | T5: =VLOOKUP(N5,BD_MEDUCA!$A$4583:$M$4587,13,TRUE) -> NO ESPECIFICADO | U5: =VLOOKUP(N5,BD_MEDUCA!$A$4583:$M$4587,2,TRUE) -> SUBSISTEMA REGULAR
A6: 1 | B6: 69 | C6: Biblioteca Pública Generosa Valdez de Diaz | D6: Chiriquí | E6: Barú | F6: Puerto Tomás Armuelles | G6: FO | H6: 8.277919 | I6: -82.864167 | J6: 04/05/2017 | K6: =VLOOKUP(C6,BD_SESIONES_DE_USUARIO!A6:H65,7,FALSE) -> C&W Panamá | L6: =VLOOKUP(C6,BD_SESIONES_DE_USUARIO!A6:H65,5,FALSE) -> 552 | M6: =VLOOKUP(C6,BD_DATA_TRANSFERIDA!A6:G65,5,FALSE) -> 48 | O6: =VLOOKUP(N6,BD_MEDUCA!$A$4583:$M$4587,3,TRUE) -> #N/A | P6: =VLOOKUP(N6,BD_MEDUCA!$A$4583:$M$4587,4,TRUE) -> #N/A | Q6: =VLOOKUP(N6,BD_MEDUCA!$A$4583:$M$4587,10,TRUE) -> #N/A | R6: =VLOOKUP(N6,BD_MEDUCA!$A$4583:$M$4587,11,TRUE) -> #N/A | S6: =VLOOKUP(N6,BD_MEDUCA!$A$4583:$M$4587,12,TRUE) -> #N/A | T6: =VLOOKUP(N6,BD_MEDUCA!$A$4583:$M$4587,13,TRUE) -> #N/A | U6: =VLOOKUP(N6,BD_MEDUCA!$A$4583:$M$4587,2,TRUE) -> #N/A
A7: 1 | B7: 70 | C7: Bomberos Puerto Armuelles | D7: Chiriquí | E7: Barú | F7: Puerto Tomás Armuelles | G7: FO | H7: 8.271352 | I7: -82.863631 | J7: 04/05/2017 | K7: =VLOOKUP(C7,BD_SESIONES_DE_USUARIO!A7:H66,7,FALSE) -> C&W Panamá | L7: =VLOOKUP(C7,BD_SESIONES_DE_USUARIO!A7:H66,5,FALSE) -> 878 | M7: =VLOOKUP(C7,BD_DATA_TRANSFERIDA!A7:G66,5,FALSE) -> 49 | O7: =VLOOKUP(N7,BD_MEDUCA!$A$4583:$M$4587,3,TRUE) -> #N/A | P7: =VLOOKUP(N7,BD_MEDUCA!$A$4583:$M$4587,4,TRUE) -> #N/A | Q7: =VLOOKUP(N7,BD_MEDUCA!$A$4583:$M$4587,10,TRUE) -> #N/A | R7: =VLOOKUP(N7,BD_MEDUCA!$A$4583:$M$4587,11,TRUE) -> #N/A | S7: =VLOOKUP(N7,BD_MEDUCA!$A$4583:$M$4587,12,TRUE) -> #N/A | T7: =VLOOKUP(N7,BD_MEDUCA!$A$4583:$M$4587,13,TRUE) -> #N/A | U7: =VLOOKUP(N7,BD_MEDUCA!$A$4583:$M$4587,2,TRUE) -> #N/A
A8: 1 | B8: 71 | C8: Esc. Los Ángeles | D8: Chiriquí | E8: Barú | F8: Puerto Tomás Armuelles | G8: FO | H8: 8.272968 | I8: -82.861328 | J8: 24/05/2017 | K8: =VLOOKUP(C8,BD_SESIONES_DE_USUARIO!A8:H67,7,FALSE) -> C&W Panamá | L8: =VLOOKUP(C8,BD_SESIONES_DE_USUARIO!A8:H67,5,FALSE) -> 1083 | M8: =VLOOKUP(C8,BD_DATA_TRANSFERIDA!A8:G67,5,FALSE) -> 113 | N8: ESC. LOS ANGELES | O8: =VLOOKUP(N8,BD_MEDUCA!$A$4583:$M$4587,3,TRUE) -> OFICIAL | P8: =VLOOKUP(N8,BD_MEDUCA!$A$4583:$M$4587,4,TRUE) -> CULTURA Y DEPORTE | Q8: =VLOOKUP(N8,BD_MEDUCA!$A$4583:$M$4587,10,TRUE) -> URBANA | R8: =VLOOKUP(N8,BD_MEDUCA!$A$4583:$M$4587,11,TRUE) -> NO | S8: =VLOOKUP(N8,BD_MEDUCA!$A$4583:$M$4587,12,TRUE) -> No | T8: =VLOOKUP(N8,BD_MEDUCA!$A$4583:$M$4587,13,TRUE) -> NO ESPECIFICADO | U8: =VLOOKUP(N8,BD_MEDUCA!$A$4583:$M$4587,2,TRUE) -> SUBSISTEMA REGULAR
A9: 1 | B9: 72 | C9: Esc. Márgenes de Corotú | D9: Chiriquí | E9: Barú | F9: Puerto Tomás Armuelles | G9: FO | H9: 8.272843 | I9: -82.894507 | J9: 24/05/2017 | K9: =VLOOKUP(C9,BD_SESIONES_DE_USUARIO!A9:H68,7,FALSE) -> C&W Panamá | L9: =VLOOKUP(C9,BD_SESIONES_DE_USUARIO!A9:H68,5,FALSE) -> 3110 | M9: =VLOOKUP(C9,BD_DATA_TRANSFERIDA!A9:G68,5,FALSE) -> 586 | N9: ESC. MARGENES DE COROTU | O9: =VLOOKUP(N9,BD_MEDUCA!$A$4583:$M$4587,3,TRUE) -> OFICIAL | P9: =VLOOKUP(N9,BD_MEDUCA!$A$4583:$M$4587,4,TRUE) -> CULTURA Y DEPORTE | Q9: =VLOOKUP(N9,BD_MEDUCA!$A$4583:$M$4587,10,TRUE) -> URBANA | R9: =VLOOKUP(N9,BD_MEDUCA!$A$4583:$M$4587,11,TRUE) -> NO | S9: =VLOOKUP(N9,BD_MEDUCA!$A$4583:$M$4587,12,TRUE) -> No | T9: =VLOOKUP(N9,BD_MEDUCA!$A$4583:$M$4587,13,TRUE) -> NO ESPECIFICADO | U9: =VLOOKUP(N9,BD_MEDUCA!$A$4583:$M$4587,2,TRUE) -> SUBSISTEMA REGULAR
A10: 1 | B10: 74 | C10: Esc. Sec. de Puerto Armuelles | D10: Chiriquí | E10: Barú | F10: Puerto Tomás Armuelles | G10: FO | H10: 8.284577 | I10: -82.863122 | J10: 04/05/2017 | K10: =VLOOKUP(C10,BD_SESIONES_DE_USUARIO!A10:H69,7,FALSE) -> C&W Panamá | L10: =VLOOKUP(C10,BD_SESIONES_DE_USUARIO!A10:H69,5,FALSE) -> 3045 | M10: =VLOOKUP(C10,BD_DATA_TRANSFERIDA!A10:G69,5,FALSE) -> 81 | N10: ESC. SEC. DE PUERTO ARMUELLES. | O10: =VLOOKUP(N10,BD_MEDUCA!$A$4583:$M$4587,3,TRUE) -> OFICIAL | P10: =VLOOKUP(N10,BD_MEDUCA!$A$4583:$M$4587,4,TRUE) -> CULTURA Y DEPORTE | Q10: =VLOOKUP(N10,BD_MEDUCA!$A$4583:$M$4587,10,TRUE) -> URBANA | R10: =VLOOKUP(N10,BD_MEDUCA!$A$4583:$M$4587,11,TRUE) -> NO | S10: =VLOOKUP(N10,BD_MEDUCA!$A$4583:$M$4587,12,TRUE) -> No | T10: =VLOOKUP(N10,BD_MEDUCA!$A$4583:$M$4587,13,TRUE) -> NO ESPECIFICADO | U10: =VLOOKUP(N10,BD_MEDUCA!$A$4583:$M$4587,2,TRUE) -> SUBSISTEMA REGULAR
A11: 1 | B11: 75 | C11: Esc. Tomás Armuelles | D11: Chiriquí | E11: Barú | F11: Puerto Tomás Armuelles | G11: PTP | H11: 8.270955 | I11: -82.859721 | J11: 24/05/2017 | K11: =VLOOKUP(C11,BD_SESIONES_DE_USUARIO!A11:H70,7,FALSE) -> C&W Panamá | L11: =VLOOKUP(C11,BD_SESIONES_DE_USUARIO!A11:H70,5,FALSE) -> 1707 | M11: =VLOOKUP(C11,BD_DATA_TRANSFERIDA!A11:G70,5,FALSE) -> 188 | N11: ESC. TOMAS ARMUELLES | O11: =VLOOKUP(N11,BD_MEDUCA!$A$4583:$M$4587,3,TRUE) -> OFICIAL | P11: =VLOOKUP(N11,BD_MEDUCA!$A$4583:$M$4587,4,TRUE) -> CULTURA Y DEPORTE | Q11: =VLOOKUP(N11,BD_MEDUCA!$A$4583:$M$4587,10,TRUE) -> URBANA | R11: =VLOOKUP(N11,BD_MEDUCA!$A$4583:$M$4587,11,TRUE) -> NO | S11: =VLOOKUP(N11,BD_MEDUCA!$A$4583:$M$4587,12,TRUE) -> No | T11: =VLOOKUP(N11,BD_MEDUCA!$A$4583:$M$4587,13,TRUE) -> NO ESPECIFICADO | U11: =VLOOKUP(N11,BD_MEDUCA!$A$4583:$M$4587,2,TRUE) -> SUBSISTEMA REGULAR
A12: 1 | B12: 77 | C12: Municipio Puerto Armuelles | D12: Chiriquí | E12: Barú | F12: Puerto Tomás Armuelles | G12: FO | H12: 8.273669 | I12: -82.860183 | J12: 04/05/2017 | K12: =VLOOKUP(C12,BD_SESIONES_DE_USUARIO!A12:H71,7,FALSE) -> C&W Panamá | L12: =VLOOKUP(C12,BD_SESIONES_DE_USUARIO!A12:H71,5,FALSE) -> 2776 | M12: =VLOOKUP(C12,BD_DATA_TRANSFERIDA!A12:G71,5,FALSE) -> 70 | O12: =VLOOKUP(N12,BD_MEDUCA!$A$4583:$M$4587,3,TRUE) -> #N/A | P12: =VLOOKUP(N12,BD_MEDUCA!$A$4583:$M$4587,4,TRUE) -> #N/A | Q12: =VLOOKUP(N12,BD_MEDUCA!$A$4583:$M$4587,10,TRUE) -> #N/A | R12: =VLOOKUP(N12,BD_MEDUCA!$A$4583:$M$4587,11,TRUE) -> #N/A | S12: =VLOOKUP(N12,BD_MEDUCA!$A$4583:$M$4587,12,TRUE) -> #N/A | T12: =VLOOKUP(N12,BD_MEDUCA!$A$4583:$M$4587,13,TRUE) -> #N/A | U12: =VLOOKUP(N12,BD_MEDUCA!$A$4583:$M$4587,2,TRUE) -> #N/A
A13: 1 | B13: 78 | C13: Parque Central Puerto Armuelles | D13: Chiriquí | E13: Barú | F13: Puerto Tomás Armuelles | G13: FO | H13: 8.271562 | I13: -82.86013 | J13: 04/05/2017 | K13: =VLOOKUP(C13,BD_SESIONES_DE_USUARIO!A13:H72,7,FALSE) -> C&W Panamá | L13: =VLOOKUP(C13,BD_SESIONES_DE_USUARIO!A13:H72,5,FALSE) -> 3470 | M13: =VLOOKUP(C13,BD_DATA_TRANSFERIDA!A13:G72,5,FALSE) -> 248 | O13: =VLOOKUP(N13,BD_MEDUCA!$A$4583:$M$4587,3,TRUE) -> #N/A | P13: =VLOOKUP(N13,BD_MEDUCA!$A$4583:$M$4587,4,TRUE) -> #N/A | Q13: =VLOOKUP(N13,BD_MEDUCA!$A$4583:$M$4587,10,TRUE) -> #N/A | R13: =VLOOKUP(N13,BD_MEDUCA!$A$4583:$M$4587,11,TRUE) -> #N/A | S13: =VLOOKUP(N13,BD_MEDUCA!$A$4583:$M$4587,12,TRUE) -> #N/A | T13: =VLOOKUP(N13,BD_MEDUCA!$A$4583:$M$4587,13,TRUE) -> #N/A | U13: =VLOOKUP(N13,BD_MEDUCA!$A$4583:$M$4587,2,TRUE) -> #N/A
A14: 1 | B14: 79 | C14: Esc. Agua Buena | D14: Chiriquí | E14: Barú | F14: Puerto Tomás Armuelles | G14: FO | H14: 8.302843 | I14: -82.872246 | J14: 04/05/2017 | K14: =VLOOKUP(C14,BD_SESIONES_DE_USUARIO!A14:H73,7,FALSE) -> C&W Panamá | L14: =VLOOKUP(C14,BD_SESIONES_DE_USUARIO!A14:H73,5,FALSE) -> 502 | M14: =VLOOKUP(C14,BD_DATA_TRANSFERIDA!A14:G73,5,FALSE) -> 55 | N14: ESC. AGUA BUENA | O14: =VLOOKUP(N14,BD_MEDUCA!$A$4583:$M$4587,3,TRUE) -> OFICIAL | P14: =VLOOKUP(N14,BD_MEDUCA!$A$4583:$M$4587,4,TRUE) -> CULTURA Y DEPORTE | Q14: =VLOOKUP(N14,BD_MEDUCA!$A$4583:$M$4587,10,TRUE) -> URBANA | R14: =VLOOKUP(N14,BD_MEDUCA!$A$4583:$M$4587,11,TRUE) -> NO | S14: =VLOOKUP(N14,BD_MEDUCA!$A$4583:$M$4587,12,TRUE) -> No | T14: =VLOOKUP(N14,BD_MEDUCA!$A$4583:$M$4587,13,TRUE) -> NO ESPECIFICADO | U14: =VLOOKUP(N14,BD_MEDUCA!$A$4583:$M$4587,2,TRUE) -> SUBSISTEMA REGULAR
A15: 1 | B15: 80 | C15: Esc. El Palmar | D15: Chiriquí | E15: Barú | F15: Puerto Tomás Armuelles | G15: FO | H15: 8.308957 | I15: -82.840718 | J15: 25/07/2017 | K15: =VLOOKUP(C15,BD_SESIONES_DE_USUARIO!A15:H74,7,FALSE) -> C&W Panamá | L15: =VLOOKUP(C15,BD_SESIONES_DE_USUARIO!A15:H74,5,FALSE) -> 2651 | M15: =VLOOKUP(C15,BD_DATA_TRANSFERIDA!A15:G74,5,FALSE) -> 191 | N15: ESC. BILINGÜE EL PALMAR | O15: =VLOOKUP(N15,BD_MEDUCA!$A$4583:$M$4587,3,TRUE) -> OFICIAL | P15: =VLOOKUP(N15,BD_MEDUCA!$A$4583:$M$4587,4,TRUE) -> CULTURA Y DEPORTE | Q15: =VLOOKUP(N15,BD_MEDUCA!$A$4583:$M$4587,10,TRUE) -> URBANA | R15: =VLOOKUP(N15,BD_MEDUCA!$A$4583:$M$4587,11,TRUE) -> NO | S15: =VLOOKUP(N15,BD_MEDUCA!$A$4583:$M$4587,12,TRUE) -> No | T15: =VLOOKUP(N15,BD_MEDUCA!$A$4583:$M$4587,13,TRUE) -> NO ESPECIFICADO | U15: =VLOOKUP(N15,BD_MEDUCA!$A$4583:$M$4587,2,TRUE) -> SUBSISTEMA REGULAR
A16: 1 | B16: 81 | C16: Esc. Flor de Lima | D16: Chiriquí | E16: Barú | F16: Puerto Tomás Armuelles | G16: FO | H16: 8.294459 | I16: -82.857206 | J16: 24/05/2017 | K16: =VLOOKUP(C16,BD_SESIONES_DE_USUARIO!A16:H75,7,FALSE) -> C&W Panamá | L16: =VLOOKUP(C16,BD_SESIONES_DE_USUARIO!A16:H75,5,FALSE) -> 886 | M16: =VLOOKUP(C16,BD_DATA_TRANSFERIDA!A16:G75,5,FALSE) -> 99 | N16: ESC. FLOR DE LIMA | O16: =VLOOKUP(N16,BD_MEDUCA!$A$4583:$M$4587,3,TRUE) -> OFICIAL | P16: =VLOOKUP(N16,BD_MEDUCA!$A$4583:$M$4587,4,TRUE) -> CULTURA Y DEPORTE | Q16: =VLOOKUP(N16,BD_MEDUCA!$A$4583:$M$4587,10,TRUE) -> URBANA | R16: =VLOOKUP(N16,BD_MEDUCA!$A$4583:$M$4587,11,TRUE) -> NO | S16: =VLOOKUP(N16,BD_MEDUCA!$A$4583:$M$4587,12,TRUE) -> No | T16: =VLOOKUP(N16,BD_MEDUCA!$A$4583:$M$4587,13,TRUE) -> NO ESPECIFICADO | U16: =VLOOKUP(N16,BD_MEDUCA!$A$4583:$M$4587,2,TRUE) -> SUBSISTEMA REGULAR
A17: 1 | B17: 83 | C17: Esc. Aguacatón | D17: Chiriquí | E17: Barú | F17: Rodolfo Aguilar Delgado | G17: FO | H17: 8.347584 | I17: -82.801082 | J17: 30/05/2017 | K17: =VLOOKUP(C17,BD_SESIONES_DE_USUARIO!A17:H76,7,FALSE) -> C&W Panamá | L17: =VLOOKUP(C17,BD_SESIONES_DE_USUARIO!A17:H76,5,FALSE) -> 218 | M17: =VLOOKUP(C17,BD_DATA_TRANSFERIDA!A17:G76,5,FALSE) -> 18 | N17: C.E.B.G. AGUACATON | O17: =VLOOKUP(N17,BD_MEDUCA!$A$4583:$M$4587,3,TRUE) -> OFICIAL | P17: =VLOOKUP(N17,BD_MEDUCA!$A$4583:$M$4587,4,TRUE) -> CULTURA Y DEPORTE | Q17: =VLOOKUP(N17,BD_MEDUCA!$A$4583:$M$4587,10,TRUE) -> URBANA | R17: =VLOOKUP(N17,BD_MEDUCA!$A$4583:$M$4587,11,TRUE) -> NO | S17: =VLOOKUP(N17,BD_MEDUCA!$A$4583:$M$4587,12,TRUE) -> No | T17: =VLOOKUP(N17,BD_MEDUCA!$A$4583:$M$4587,13,TRUE) -> NO ESPECIFICADO | U17: =VLOOKUP(N17,BD_MEDUCA!$A$4583:$M$4587,2,TRUE) -> SUBSISTEMA REGULAR
A18: 1 | B18: 84 | C18: Esc. Balsa | D18: Chiriquí | E18: Barú | F18: Rodolfo Aguilar Delgado | G18: FO | H18: 8.428309 | I18: -82.895269 | J18: 23/05/2017 | K18: =VLOOKUP(C18,BD_SESIONES_DE_USUARIO!A18:H77,7,FALSE) -> C&W Panamá | L18: =VLOOKUP(C18,BD_SESIONES_DE_USUARIO!A18:H77,5,FALSE) -> 2262 | M18: =VLOOKUP(C18,BD_DATA_TRANSFERIDA!A18:G77,5,FALSE) -> 437 | N18: C.E.B.G. BALSA | O18: =VLOOKUP(N18,BD_MEDUCA!$A$4583:$M$4587,3,TRUE) -> OFICIAL | P18: =VLOOKUP(N18,BD_MEDUCA!$A$4583:$M$4587,4,TRUE) -> CULTURA Y DEPORTE | Q18: =VLOOKUP(N18,BD_MEDUCA!$A$4583:$M$4587,10,TRUE) -> URBANA | R18: =VLOOKUP(N18,BD_MEDUCA!$A$4583:$M$4587,11,TRUE) -> NO | S18: =VLOOKUP(N18,BD_MEDUCA!$A$4583:$M$4587,12,TRUE) -> No | T18: =VLOOKUP(N18,BD_MEDUCA!$A$4583:$M$4587,13,TRUE) -> NO ESPECIFICADO | U18: =VLOOKUP(N18,BD_MEDUCA!$A$4583:$M$4587,2,TRUE) -> SUBSISTEMA REGULAR
A19: 1 | B19: 85 | C19: Esc. Burica Centro | D19: Chiriquí | E19: Barú | F19: Rodolfo Aguilar Delgado | G19: PTP | H19: 8.391051 | I19: -82.903279 | J19: 25/07/2017 | K19: =VLOOKUP(C19,BD_SESIONES_DE_USUARIO!A19:H78,7,FALSE) -> C&W Panamá | L19: =VLOOKUP(C19,BD_SESIONES_DE_USUARIO!A19:H78,5,FALSE) -> 1272 | M19: =VLOOKUP(C19,BD_DATA_TRANSFERIDA!A19:G78,5,FALSE) -> 173 | N19: ESC. BURICA CENTRO | O19: =VLOOKUP(N19,BD_MEDUCA!$A$4583:$M$4587,3,TRUE) -> OFICIAL | P19: =VLOOKUP(N19,BD_MEDUCA!$A$4583:$M$4587,4,TRUE) -> CULTURA Y DEPORTE | Q19: =VLOOKUP(N19,BD_MEDUCA!$A$4583:$M$4587,10,TRUE) -> URBANA | R19: =VLOOKUP(N19,BD_MEDUCA!$A$4583:$M$4587,11,TRUE) -> NO | S19: =VLOOKUP(N19,BD_MEDUCA!$A$4583:$M$4587,12,TRUE) -> No | T19: =VLOOKUP(N19,BD_MEDUCA!$A$4583:$M$4587,13,TRUE) -> NO ESPECIFICADO | U19: =VLOOKUP(N19,BD_MEDUCA!$A$4583:$M$4587,2,TRUE) -> SUBSISTEMA REGULAR
A20: 1 | B20: 86 | C20: Esc. Corozo | D20: Chiriquí | E20: Barú | F20: Rodolfo Aguilar Delgado | G20: FO | H20: 8.415213 | I20: -82.931435 | J20: 04/08/2017 | K20: =VLOOKUP(C20,BD_SESIONES_DE_USUARIO!A20:H79,7,FALSE) -> C&W Panamá | L20: =VLOOKUP(C20,BD_SESIONES_DE_USUARIO!A20:H79,5,FALSE) -> 1504 | M20: =VLOOKUP(C20,BD_DATA_TRANSFERIDA!A20:G79,5,FALSE) -> 259 | N20: ESC. COROZO | O20: =VLOOKUP(N20,BD_MEDUCA!$A$4583:$M$4587,3,TRUE) -> OFICIAL | P20: =VLOOKUP(N20,BD_MEDUCA!$A$4583:$M$4587,4,TRUE) -> CULTURA Y DEPORTE | Q20: =VLOOKUP(N20,BD_MEDUCA!$A$4583:$M$4587,10,TRUE) -> URBANA | R20: =VLOOKUP(N20,BD_MEDUCA!$A$4583:$M$4587,11,TRUE) -> NO | S20: =VLOOKUP(N20,BD_MEDUCA!$A$4583:$M$4587,12,TRUE) -> No | T20: =VLOOKUP(N20,BD_MEDUCA!$A$4583:$M$4587,13,TRUE) -> NO ESPECIFICADO | U20: =VLOOKUP(N20,BD_MEDUCA!$A$4583:$M$4587,2,TRUE) -> SUBSISTEMA REGULAR
A21: 1 | B21: 87 | C21: Esc. Finca Blanco | D21: Chiriquí | E21: Barú | F21: Rodolfo Aguilar Delgado | G21: FO | H21: 8.384487 | I21: -82.875077 | J21: 05/05/2017 | K21: =VLOOKUP(C21,BD_SESIONES_DE_USUARIO!A21:H80,7,FALSE) -> C&W Panamá | L21: =VLOOKUP(C21,BD_SESIONES_DE_USUARIO!A21:H80,5,FALSE) -> 1340 | M21: =VLOOKUP(C21,BD_DATA_TRANSFERIDA!A21:G80,5,FALSE) -> 81 | N21: C.E.B.G. FINCA BLANCO | O21: =VLOOKUP(N21,BD_MEDUCA!$A$4583:$M$4587,3,TRUE) -> OFICIAL | P21: =VLOOKUP(N21,BD_MEDUCA!$A$4583:$M$4587,4,TRUE) -> CULTURA Y DEPORTE | Q21: =VLOOKUP(N21,BD_MEDUCA!$A$4583:$M$4587,10,TRUE) -> URBANA | R21: =VLOOKUP(N21,BD_MEDUCA!$A$4583:$M$4587,11,TRUE) -> NO | S21: =VLOOKUP(N21,BD_MEDUCA!$A$4583:$M$4587,12,TRUE) -> No | T21: =VLOOKUP(N21,BD_MEDUCA!$A$4583:$M$4587,13,TRUE) -> NO ESPECIFICADO | U21: =VLOOKUP(N21,BD_MEDUCA!$A$4583:$M$4587,2,TRUE) -> SUBSISTEMA REGULAR
A22: 1 | B22: 88 | C22: Esc. Finca Bongo | D22: Chiriquí | E22: Barú | F22: Rodolfo Aguilar Delgado | G22: FO | H22: 8.406384 | I22: -82.904103 | J22: 30/05/2017 | K22: =VLOOKUP(C22,BD_SESIONES_DE_USUARIO!A22:H81,7,FALSE) -> C&W Panamá | L22: =VLOOKUP(C22,BD_SESIONES_DE_USUARIO!A22:H81,5,FALSE) -> 1738 | M22: =VLOOKUP(C22,BD_DATA_TRANSFERIDA!A22:G81,5,FALSE) -> 360 | N22: ESC. BONGO | O22: =VLOOKUP(N22,BD_MEDUCA!$A$4583:$M$4587,3,TRUE) -> OFICIAL | P22: =VLOOKUP(N22,BD_MEDUCA!$A$4583:$M$4587,4,TRUE) -> CULTURA Y DEPORTE | Q22: =VLOOKUP(N22,BD_MEDUCA!$A$4583:$M$4587,10,TRUE) -> URBANA | R22: =VLOOKUP(N22,BD_MEDUCA!$A$4583:$M$4587,11,TRUE) -> NO | S22: =VLOOKUP(N22,BD_MEDUCA!$A$4583:$M$4587,12,TRUE) -> No | T22: =VLOOKUP(N22,BD_MEDUCA!$A$4583:$M$4587,13,TRUE) -> NO ESPECIFICADO | U22: =VLOOKUP(N22,BD_MEDUCA!$A$4583:$M$4587,2,TRUE) -> SUBSISTEMA REGULAR
A23: 1 | B23: 89 | C23: Esc. Finca Zapatero | D23: Chiriquí | E23: Barú | F23: Rodolfo Aguilar Delgado | G23: FO | H23: 8.397342 | I23: -82.891426 | J23: 30/05/2017 | K23: =VLOOKUP(C23,BD_SESIONES_DE_USUARIO!A23:H82,7,FALSE) -> C&W Panamá | L23: =VLOOKUP(C23,BD_SESIONES_DE_USUARIO!A23:H82,5,FALSE) -> 2852 | M23: =VLOOKUP(C23,BD_DATA_TRANSFERIDA!A23:G82,5,FALSE) -> 328 | N23: ESC. FINCA ZAPATERO | O23: =VLOOKUP(N23,BD_MEDUCA!$A$4583:$M$4587,3,TRUE) -> OFICIAL | P23: =VLOOKUP(N23,BD_MEDUCA!$A$4583:$M$4587,4,TRUE) -> CULTURA Y DEPORTE | Q23: =VLOOKUP(N23,BD_MEDUCA!$A$4583:$M$4587,10,TRUE) -> URBANA | R23: =VLOOKUP(N23,BD_MEDUCA!$A$4583:$M$4587,11,TRUE) -> NO | S23: =VLOOKUP(N23,BD_MEDUCA!$A$4583:$M$4587,12,TRUE) -> No | T23: =VLOOKUP(N23,BD_MEDUCA!$A$4583:$M$4587,13,TRUE) -> NO ESPECIFICADO | U23: =VLOOKUP(N23,BD_MEDUCA!$A$4583:$M$4587,2,TRUE) -> SUBSISTEMA REGULAR
A24: 1 | B24: 90 | C24: Esc. Guayacán | D24: Chiriquí | E24: Barú | F24: Rodolfo Aguilar Delgado | G24: FO | H24: 8.349596 | I24: -82.833844 | J24: 30/05/2017 | K24: =VLOOKUP(C24,BD_SESIONES_DE_USUARIO!A24:H83,7,FALSE) -> C&W Panamá | L24: =VLOOKUP(C24,BD_SESIONES_DE_USUARIO!A24:H83,5,FALSE) -> 3589 | M24: =VLOOKUP(C24,BD_DATA_TRANSFERIDA!A24:G83,5,FALSE) -> 592 | N24: ESC. GUAYACAN | O24: =VLOOKUP(N24,BD_MEDUCA!$A$4583:$M$4587,3,TRUE) -> OFICIAL | P24: =VLOOKUP(N24,BD_MEDUCA!$A$4583:$M$4587,4,TRUE) -> CULTURA Y DEPORTE | Q24: =VLOOKUP(N24,BD_MEDUCA!$A$4583:$M$4587,10,TRUE) -> URBANA | R24: =VLOOKUP(N24,BD_MEDUCA!$A$4583:$M$4587,11,TRUE) -> NO | S24: =VLOOKUP(N24,BD_MEDUCA!$A$4583:$M$4587,12,TRUE) -> No | T24: =VLOOKUP(N24,BD_MEDUCA!$A$4583:$M$4587,13,TRUE) -> NO ESPECIFICADO | U24: =VLOOKUP(N24,BD_MEDUCA!$A$4583:$M$4587,2,TRUE) -> SUBSISTEMA REGULAR
A25: 1 | B25: 91 | C25: Esc. Higuerón | D25: Chiriquí | E25: Barú | F25: Rodolfo Aguilar Delgado | G25: PTP | H25: 8.407189 | I25: -82.888167 | J25: 25/07/2017 | K25: =VLOOKUP(C25,BD_SESIONES_DE_USUARIO!A25:H84,7,FALSE) -> C&W Panamá | L25: =VLOOKUP(C25,BD_SESIONES_DE_USUARIO!A25:H84,5,FALSE) -> 2174 | M25: =VLOOKUP(C25,BD_DATA_TRANSFERIDA!A25:G84,5,FALSE) -> 265 | N25: C.E.B.G. HIGUERON | O25: =VLOOKUP(N25,BD_MEDUCA!$A$4583:$M$4587,3,TRUE) -> OFICIAL | P25: =VLOOKUP(N25,BD_MEDUCA!$A$4583:$M$4587,4,TRUE) -> CULTURA Y DEPORTE | Q25: =VLOOKUP(N25,BD_MEDUCA!$A$4583:$M$4587,10,TRUE) -> URBANA | R25: =VLOOKUP(N25,BD_MEDUCA!$A$4583:$M$4587,11,TRUE) -> NO | S25: =VLOOKUP(N25,BD_MEDUCA!$A$4583:$M$4587,12,TRUE) -> No | T25: =VLOOKUP(N25,BD_MEDUCA!$A$4583:$M$4587,13,TRUE) -> NO ESPECIFICADO | U25: =VLOOKUP(N25,BD_MEDUCA!$A$4583:$M$4587,2,TRUE) -> SUBSISTEMA REGULAR
... A34: 1 | B34: 219 | C34: Esc. El Flor | D34: Chiriquí | E34: Dolega | F34: Los Algarrobos | G34: HFC | H34: 8.575638 | I34: -82.443582 | J34: 29/05/2017 | K34: =VLOOKUP(C34,BD_SESIONES_DE_USUARIO!A34:H93,7,FALSE) -> C&W Panamá | L34: =VLOOKUP(C34,BD_SESIONES_DE_USUARIO!A34:H93,5,FALSE) -> 150 | M34: =VLOOKUP(C34,BD_DATA_TRANSFERIDA!A34:G93,5,FALSE) -> 9 | N34: C.E.B.G. EL FLOR | O34: =VLOOKUP(N34,BD_MEDUCA!$A$4583:$M$4587,3,TRUE) -> OFICIAL | P34: =VLOOKUP(N34,BD_MEDUCA!$A$4583:$M$4587,4,TRUE) -> CULTURA Y DEPORTE | Q34: =VLOOKUP(N34,BD_MEDUCA!$A$4583:$M$4587,10,TRUE) -> URBANA | R34: =VLOOKUP(N34,BD_MEDUCA!$A$4583:$M$4587,11,TRUE) -> NO | S34: =VLOOKUP(N34,BD_MEDUCA!$A$4583:$M$4587,12,TRUE) -> No | T34: =VLOOKUP(N34,BD_MEDUCA!$A$4583:$M$4587,13,TRUE) -> NO ESPECIFICADO | U34: =VLOOKUP(N34,BD_MEDUCA!$A$4583:$M$4587,2,TRUE) -> SUBSISTEMA REGULAR
A35: 1 | B35: 220 | C35: Municipio de Dolega | D35: Chiriquí | E35: Dolega | F35: Los Algarrobos | G35: HFC | H35: 8.566958 | I35: -82.416614 | J35: 26/05/2017 | K35: =VLOOKUP(C35,BD_SESIONES_DE_USUARIO!A35:H94,7,FALSE) -> C&W Panamá | L35: =VLOOKUP(C35,BD_SESIONES_DE_USUARIO!A35:H94,5,FALSE) -> 664 | M35: =VLOOKUP(C35,BD_DATA_TRANSFERIDA!A35:G94,5,FALSE) -> 23 | O35: =VLOOKUP(N35,BD_MEDUCA!$A$4583:$M$4587,3,TRUE) -> #N/A | P35: =VLOOKUP(N35,BD_MEDUCA!$A$4583:$M$4587,4,TRUE) -> #N/A | Q35: =VLOOKUP(N35,BD_MEDUCA!$A$4583:$M$4587,10,TRUE) -> #N/A | R35: =VLOOKUP(N35,BD_MEDUCA!$A$4583:$M$4587,11,TRUE) -> #N/A | S35: =VLOOKUP(N35,BD_MEDUCA!$A$4583:$M$4587,12,TRUE) -> #N/A | T35: =VLOOKUP(N35,BD_MEDUCA!$A$4583:$M$4587,13,TRUE) -> #N/A | U35: =VLOOKUP(N35,BD_MEDUCA!$A$4583:$M$4587,2,TRUE) -> #N/A
A36: 1 | B36: 221 | C36: Esc. Las Cañas. | D36: Chiriquí | E36: Dolega | F36: Los Algarrobos | G36: FO | H36: 8.56458 | I36: -82.44958 | J36: 01/08/2017 | K36: =VLOOKUP(C36,BD_SESIONES_DE_USUARIO!A36:H95,7,FALSE) -> C&W Panamá | L36: =VLOOKUP(C36,BD_SESIONES_DE_USUARIO!A36:H95,5,FALSE) -> 613 | M36: =VLOOKUP(C36,BD_DATA_TRANSFERIDA!A36:G95,5,FALSE) -> 40 | N36: C.E.B.G. LAS CAÑAS | O36: =VLOOKUP(N36,BD_MEDUCA!$A$4583:$M$4587,3,TRUE) -> OFICIAL | P36: =VLOOKUP(N36,BD_MEDUCA!$A$4583:$M$4587,4,TRUE) -> CULTURA Y DEPORTE | Q36: =VLOOKUP(N36,BD_MEDUCA!$A$4583:$M$4587,10,TRUE) -> URBANA | R36: =VLOOKUP(N36,BD_MEDUCA!$A$4583:$M$4587,11,TRUE) -> NO | S36: =VLOOKUP(N36,BD_MEDUCA!$A$4583:$M$4587,12,TRUE) -> No | T36: =VLOOKUP(N36,BD_MEDUCA!$A$4583:$M$4587,13,TRUE) -> NO ESPECIFICADO | U36: =VLOOKUP(N36,BD_MEDUCA!$A$4583:$M$4587,2,TRUE) -> SUBSISTEMA REGULAR
A37: 1 | B37: 223 | C37: Esc. Los Bejucos | D37: Chiriquí | E37: Dolega | F37: Los Algarrobos | G37: Satelital | H37: 8.585568 | I37: -82.462704 | J37: 16/10/2017 | K37: =VLOOKUP(C37,BD_SESIONES_DE_USUARIO!A37:H96,7,FALSE) -> C&W Panamá | L37: =VLOOKUP(C37,BD_SESIONES_DE_USUARIO!A37:H96,5,FALSE) -> 45 | M37: =VLOOKUP(C37,BD_DATA_TRANSFERIDA!A37:G96,5,FALSE) -> 0 | N37: ESC. LOS BEJUCOS | O37: =VLOOKUP(N37,BD_MEDUCA!$A$4583:$M$4587,3,TRUE) -> OFICIAL | P37: =VLOOKUP(N37,BD_MEDUCA!$A$4583:$M$4587,4,TRUE) -> CULTURA Y DEPORTE | Q37: =VLOOKUP(N37,BD_MEDUCA!$A$4583:$M$4587,10,TRUE) -> URBANA | R37: =VLOOKUP(N37,BD_MEDUCA!$A$4583:$M$4587,11,TRUE) -> NO | S37: =VLOOKUP(N37,BD_MEDUCA!$A$4583:$M$4587,12,TRUE) -> No | T37: =VLOOKUP(N37,BD_MEDUCA!$A$4583:$M$4587,13,TRUE) -> NO ESPECIFICADO | U37: =VLOOKUP(N37,BD_MEDUCA!$A$4583:$M$4587,2,TRUE) -> SUBSISTEMA REGULAR
A38: 1 | B38: 225 | C38: Centro de Salud Los Anastacios | D38: Chiriquí | E38: Dolega | F38: Los Anastacios | G38: FO | H38: 8.532174 | I38: -82.420761 | J38: 02/06/2017 | K38: =VLOOKUP(C38,BD_SESIONES_DE_USUARIO!A38:H97,7,FALSE) -> C&W Panamá | L38: =VLOOKUP(C38,BD_SESIONES_DE_USUARIO!A38:H97,5,FALSE) -> 1415 | M38: =VLOOKUP(C38,BD_DATA_TRANSFERIDA!A38:G97,5,FALSE) -> 160 | O38: =VLOOKUP(N38,BD_MEDUCA!$A$4583:$M$4587,3,TRUE) -> #N/A | P38: =VLOOKUP(N38,BD_MEDUCA!$A$4583:$M$4587,4,TRUE) -> #N/A | Q38: =VLOOKUP(N38,BD_MEDUCA!$A$4583:$M$4587,10,TRUE) -> #N/A | R38: =VLOOKUP(N38,BD_MEDUCA!$A$4583:$M$4587,11,TRUE) -> #N/A | S38: =VLOOKUP(N38,BD_MEDUCA!$A$4583:$M$4587,12,TRUE) -> #N/A | T38: =VLOOKUP(N38,BD_MEDUCA!$A$4583:$M$4587,13,TRUE) -> #N/A | U38: =VLOOKUP(N38,BD_MEDUCA!$A$4583:$M$4587,2,TRUE) -> #N/A
A39: 1 | B39: 226 | C39: Esc. Rincón Largo | D39: Chiriquí | E39: Dolega | F39: Los Anastacios | G39: FO | H39: 8.529598 | I39: -82.409978 | J39: 16/06/2017 | K39: =VLOOKUP(C39,BD_SESIONES_DE_USUARIO!A39:H98,7,FALSE) -> C&W Panamá | L39: =VLOOKUP(C39,BD_SESIONES_DE_USUARIO!A39:H98,5,FALSE) -> 549 | M39: =VLOOKUP(C39,BD_DATA_TRANSFERIDA!A39:G98,5,FALSE) -> 26 | N39: ESC. RINCON LARGO | O39: =VLOOKUP(N39,BD_MEDUCA!$A$4583:$M$4587,3,TRUE) -> OFICIAL | P39: =VLOOKUP(N39,BD_MEDUCA!$A$4583:$M$4587,4,TRUE) -> CULTURA Y DEPORTE | Q39: =VLOOKUP(N39,BD_MEDUCA!$A$4583:$M$4587,10,TRUE) -> URBANA | R39: =VLOOKUP(N39,BD_MEDUCA!$A$4583:$M$4587,11,TRUE) -> NO | S39: =VLOOKUP(N39,BD_MEDUCA!$A$4583:$M$4587,12,TRUE) -> No | T39: =VLOOKUP(N39,BD_MEDUCA!$A$4583:$M$4587,13,TRUE) -> NO ESPECIFICADO | U39: =VLOOKUP(N39,BD_MEDUCA!$A$4583:$M$4587,2,TRUE) -> SUBSISTEMA REGULAR
A40: 1 | B40: 227 | C40: Escuela Los Anastacios | D40: Chiriquí | E40: Dolega | F40: Los Anastacios | G40: FO | H40: 8.530478 | I40: -82.417758 | J40: 28/07/2017 | K40: =VLOOKUP(C40,BD_SESIONES_DE_USUARIO!A40:H99,7,FALSE) -> C&W Panamá | L40: =VLOOKUP(C40,BD_SESIONES_DE_USUARIO!A40:H99,5,FALSE) -> 1383 | M40: =VLOOKUP(C40,BD_DATA_TRANSFERIDA!A40:G99,5,FALSE) -> 70 | N40: ESC. LOS ANASTACIOS | O40: =VLOOKUP(N40,BD_MEDUCA!$A$4583:$M$4587,3,TRUE) -> OFICIAL | P40: =VLOOKUP(N40,BD_MEDUCA!$A$4583:$M$4587,4,TRUE) -> CULTURA Y DEPORTE | Q40: =VLOOKUP(N40,BD_MEDUCA!$A$4583:$M$4587,10,TRUE) -> URBANA | R40: =VLOOKUP(N40,BD_MEDUCA!$A$4583:$M$4587,11,TRUE) -> NO | S40: =VLOOKUP(N40,BD_MEDUCA!$A$4583:$M$4587,12,TRUE) -> No | T40: =VLOOKUP(N40,BD_MEDUCA!$A$4583:$M$4587,13,TRUE) -> NO ESPECIFICADO | U40: =VLOOKUP(N40,BD_MEDUCA!$A$4583:$M$4587,2,TRUE) -> SUBSISTEMA REGULAR
A41: 1 | B41: 228 | C41: Escuela Primaria Santa Rosa | D41: Chiriquí | E41: Dolega | F41: Los Anastacios | G41: HFC | H41: 8.532996 | I41: -82.428818 | J41: 25/05/2017 | K41: =VLOOKUP(C41,BD_SESIONES_DE_USUARIO!A41:H100,7,FALSE) -> C&W Panamá | L41: =VLOOKUP(C41,BD_SESIONES_DE_USUARIO!A41:H100,5,FALSE) -> 1016 | M41: =VLOOKUP(C41,BD_DATA_TRANSFERIDA!A41:G100,5,FALSE) -> 89 | N41: C.E.B.G. SANTA ROSA | O41: =VLOOKUP(N41,BD_MEDUCA!$A$4583:$M$4587,3,TRUE) -> OFICIAL | P41: =VLOOKUP(N41,BD_MEDUCA!$A$4583:$M$4587,4,TRUE) -> CULTURA Y DEPORTE | Q41: =VLOOKUP(N41,BD_MEDUCA!$A$4583:$M$4587,10,TRUE) -> URBANA | R41: =VLOOKUP(N41,BD_MEDUCA!$A$4583:$M$4587,11,TRUE) -> NO | S41: =VLOOKUP(N41,BD_MEDUCA!$A$4583:$M$4587,12,TRUE) -> No | T41: =VLOOKUP(N41,BD_MEDUCA!$A$4583:$M$4587,13,TRUE) -> NO ESPECIFICADO | U41: =VLOOKUP(N41,BD_MEDUCA!$A$4583:$M$4587,2,TRUE) -> SUBSISTEMA REGULAR
A42: 1 | B42: 230 | C42: Parque 27 de Noviembre | D42: Chiriquí | E42: Dolega | F42: Los Anastacios | G42: FO | H42: 8.532711 | I42: -82.419056 | J42: 01/08/2017 | K42: =VLOOKUP(C42,BD_SESIONES_DE_USUARIO!A42:H101,7,FALSE) -> C&W Panamá | L42: =VLOOKUP(C42,BD_SESIONES_DE_USUARIO!A42:H101,5,FALSE) -> 1838 | M42: =VLOOKUP(C42,BD_DATA_TRANSFERIDA!A42:G101,5,FALSE) -> 110 | O42: =VLOOKUP(N42,BD_MEDUCA!$A$4583:$M$4587,3,TRUE) -> #N/A | P42: =VLOOKUP(N42,BD_MEDUCA!$A$4583:$M$4587,4,TRUE) -> #N/A | Q42: =VLOOKUP(N42,BD_MEDUCA!$A$4583:$M$4587,10,TRUE) -> #N/A | R42: =VLOOKUP(N42,BD_MEDUCA!$A$4583:$M$4587,11,TRUE) -> #N/A | S42: =VLOOKUP(N42,BD_MEDUCA!$A$4583:$M$4587,12,TRUE) -> #N/A | T42: =VLOOKUP(N42,BD_MEDUCA!$A$4583:$M$4587,13,TRUE) -> #N/A | U42: =VLOOKUP(N42,BD_MEDUCA!$A$4583:$M$4587,2,TRUE) -> #N/A
A43: 1 | B43: 231 | C43: Parque Residencial Altamar | D43: Chiriquí | E43: Dolega | F43: Los Anastacios | G43: FO | H43: 8.520696 | I43: -82.424134 | J43: 02/06/2017 | K43: =VLOOKUP(C43,BD_SESIONES_DE_USUARIO!A43:H102,7,FALSE) -> C&W Panamá | L43: =VLOOKUP(C43,BD_SESIONES_DE_USUARIO!A43:H102,5,FALSE) -> 287 | M43: =VLOOKUP(C43,BD_DATA_TRANSFERIDA!A43:G102,5,FALSE) -> 4 | O43: =VLOOKUP(N43,BD_MEDUCA!$A$4583:$M$4587,3,TRUE) -> #N/A | P43: =VLOOKUP(N43,BD_MEDUCA!$A$4583:$M$4587,4,TRUE) -> #N/A | Q43: =VLOOKUP(N43,BD_MEDUCA!$A$4583:$M$4587,10,TRUE) -> #N/A | R43: =VLOOKUP(N43,BD_MEDUCA!$A$4583:$M$4587,11,TRUE) -> #N/A | S43: =VLOOKUP(N43,BD_MEDUCA!$A$4583:$M$4587,12,TRUE) -> #N/A | T43: =VLOOKUP(N43,BD_MEDUCA!$A$4583:$M$4587,13,TRUE) -> #N/A | U43: =VLOOKUP(N43,BD_MEDUCA!$A$4583:$M$4587,2,TRUE) -> #N/A
A44: 1 | B44: 232 | C44: Plaza Los Algarrobos | D44: Chiriquí | E44: Dolega | F44: Los Anastacios | G44: HFC | H44: 8.499541 | I44: -82.425671 | J44: 01/08/2017 | K44: =VLOOKUP(C44,BD_SESIONES_DE_USUARIO!A44:H103,7,FALSE) -> C&W Panamá | L44: =VLOOKUP(C44,BD_SESIONES_DE_USUARIO!A44:H103,5,FALSE) -> 580 | M44: =VLOOKUP(C44,BD_DATA_TRANSFERIDA!A44:G103,5,FALSE) -> 34 | O44: =VLOOKUP(N44,BD_MEDUCA!$A$4583:$M$4587,3,TRUE) -> #N/A | P44: =VLOOKUP(N44,BD_MEDUCA!$A$4583:$M$4587,4,TRUE) -> #N/A | Q44: =VLOOKUP(N44,BD_MEDUCA!$A$4583:$M$4587,10,TRUE) -> #N/A | R44: =VLOOKUP(N44,BD_MEDUCA!$A$4583:$M$4587,11,TRUE) -> #N/A | S44: =VLOOKUP(N44,BD_MEDUCA!$A$4583:$M$4587,12,TRUE) -> #N/A | T44: =VLOOKUP(N44,BD_MEDUCA!$A$4583:$M$4587,13,TRUE) -> #N/A | U44: =VLOOKUP(N44,BD_MEDUCA!$A$4583:$M$4587,2,TRUE) -> #N/A
A45: 1 | B45: 233 | C45: Esc. Higuerón. | D45: Chiriquí | E45: Gualaca | F45: Gualaca | G45: FO | H45: 8.498969 | I45: -82.285015 | J45: 02/06/2017 | K45: =VLOOKUP(C45,BD_SESIONES_DE_USUARIO!A45:H104,7,FALSE) -> C&W Panamá | L45: =VLOOKUP(C45,BD_SESIONES_DE_USUARIO!A45:H104,5,FALSE) -> 1504 | M45: =VLOOKUP(C45,BD_DATA_TRANSFERIDA!A45:G104,5,FALSE) -> 54 | N45: ESC. HIGUERON | O45: =VLOOKUP(N45,BD_MEDUCA!$A$4583:$M$4587,3,TRUE) -> OFICIAL | P45: =VLOOKUP(N45,BD_MEDUCA!$A$4583:$M$4587,4,TRUE) -> CULTURA Y DEPORTE | Q45: =VLOOKUP(N45,BD_MEDUCA!$A$4583:$M$4587,10,TRUE) -> URBANA | R45: =VLOOKUP(N45,BD_MEDUCA!$A$4583:$M$4587,11,TRUE) -> NO | S45: =VLOOKUP(N45,BD_MEDUCA!$A$4583:$M$4587,12,TRUE) -> No | T45: =VLOOKUP(N45,BD_MEDUCA!$A$4583:$M$4587,13,TRUE) -> NO ESPECIFICADO | U45: =VLOOKUP(N45,BD_MEDUCA!$A$4583:$M$4587,2,TRUE) -> SUBSISTEMA REGULAR
A46: 1 | B46: 234 | C46: Municipio Gualaca | D46: Chiriquí | E46: Gualaca | F46: Gualaca | G46: FO | H46: 8.532391 | I46: -82.299513 | J46: 02/06/2017 | K46: =VLOOKUP(C46,BD_SESIONES_DE_USUARIO!A46:H105,7,FALSE) -> C&W Panamá | L46: =VLOOKUP(C46,BD_SESIONES_DE_USUARIO!A46:H105,5,FALSE) -> 1099 | M46: =VLOOKUP(C46,BD_DATA_TRANSFERIDA!A46:G105,5,FALSE) -> 33 | O46: =VLOOKUP(N46,BD_MEDUCA!$A$4583:$M$4587,3,TRUE) -> #N/A | P46: =VLOOKUP(N46,BD_MEDUCA!$A$4583:$M$4587,4,TRUE) -> #N/A | Q46: =VLOOKUP(N46,BD_MEDUCA!$A$4583:$M$4587,10,TRUE) -> #N/A | R46: =VLOOKUP(N46,BD_MEDUCA!$A$4583:$M$4587,11,TRUE) -> #N/A | S46: =VLOOKUP(N46,BD_MEDUCA!$A$4583:$M$4587,12,TRUE) -> #N/A | T46: =VLOOKUP(N46,BD_MEDUCA!$A$4583:$M$4587,13,TRUE) -> #N/A | U46: =VLOOKUP(N46,BD_MEDUCA!$A$4583:$M$4587,2,TRUE) -> #N/A
A47: 1 | B47: 235 | C47: Parque Gualaca | D47: Chiriquí | E47: Gualaca | F47: Gualaca | G47: FO | H47: 8.533211 | I47: -82.299684 | J47: 02/06/2017 | K47: =VLOOKUP(C47,BD_SESIONES_DE_USUARIO!A47:H106,7,FALSE) -> C&W Panamá | L47: =VLOOKUP(C47,BD_SESIONES_DE_USUARIO!A47:H106,5,FALSE) -> 3656 | M47: =VLOOKUP(C47,BD_DATA_TRANSFERIDA!A47:G106,5,FALSE) -> 231 | O47: =VLOOKUP(N47,BD_MEDUCA!$A$4583:$M$4587,3,TRUE) -> #N/A | P47: =VLOOKUP(N47,BD_MEDUCA!$A$4583:$M$4587,4,TRUE) -> #N/A | Q47: =VLOOKUP(N47,BD_MEDUCA!$A$4583:$M$4587,10,TRUE) -> #N/A | R47: =VLOOKUP(N47,BD_MEDUCA!$A$4583:$M$4587,11,TRUE) -> #N/A | S47: =VLOOKUP(N47,BD_MEDUCA!$A$4583:$M$4587,12,TRUE) -> #N/A | T47: =VLOOKUP(N47,BD_MEDUCA!$A$4583:$M$4587,13,TRUE) -> #N/A | U47: =VLOOKUP(N47,BD_MEDUCA!$A$4583:$M$4587,2,TRUE) -> #N/A
A48: 1 | B48: 236 | C48: Esc. Secundaria Jesús Maria Pla | D48: Chiriquí | E48: Gualaca | F48: Gualaca | G48: FO | H48: 8.52287 | I48: -82.30013 | J48: 02/06/2017 | K48: =VLOOKUP(C48,BD_SESIONES_DE_USUARIO!A48:H107,7,FALSE) -> C&W Panamá | L48: =VLOOKUP(C48,BD_SESIONES_DE_USUARIO!A48:H107,5,FALSE) -> 1586 | M48: =VLOOKUP(C48,BD_DATA_TRANSFERIDA!A48:G107,5,FALSE) -> 34 | N48: ESC. JESUS MARIA PLA | O48: =VLOOKUP(N48,BD_MEDUCA!$A$4583:$M$4587,3,TRUE) -> OFICIAL | P48: =VLOOKUP(N48,BD_MEDUCA!$A$4583:$M$4587,4,TRUE) -> CULTURA Y DEPORTE | Q48: =VLOOKUP(N48,BD_MEDUCA!$A$4583:$M$4587,10,TRUE) -> URBANA | R48: =VLOOKUP(N48,BD_MEDUCA!$A$4583:$M$4587,11,TRUE) -> NO | S48: =VLOOKUP(N48,BD_MEDUCA!$A$4583:$M$4587,12,TRUE) -> No | T48: =VLOOKUP(N48,BD_MEDUCA!$A$4583:$M$4587,13,TRUE) -> NO ESPECIFICADO | U48: =VLOOKUP(N48,BD_MEDUCA!$A$4583:$M$4587,2,TRUE) -> SUBSISTEMA REGULAR
...

Sheet BD_SESIONES_DE_USUARIO
A1: Nombre | B1: Provincia | C1: Distrito | D1: Corregimiento | E1: Total | F1: Región | G1: Proveedor | H1: PA
A2: Esc. La Esperanza | B2: Chiriquí | C2: Barú | D2: Baco | E2: 1344 | F2: 1 | G2: C&W Panamá | H2: 64
A3: Esc. San Valentín | B3: Chiriquí | C3: Barú | D3: Baco | E3: 2053 | F3: 1 | G3: C&W Panamá | H3: 65
A4: Centro de Educ. Media de Progreso | B4: Chiriquí | C4: Barú | D4: Progreso | E4: 1633 | F4: 1 | G4: C&W Panamá | H4: 66
A5: Esc. Chuchupate | B5: Chiriquí | C5: Barú | D5: Progreso | E5: 2114 | F5: 1 | G5: C&W Panamá | H5: 68
A6: Biblioteca Pública Generosa Valdez de Diaz | B6: Chiriquí | C6: Barú | D6: Puerto Tomás Armuelles | E6: 552 | F6: 1 | G6: C&W Panamá | H6: 69
A7: Bomberos Puerto Armuelles | B7: Chiriquí | C7: Barú | D7: Puerto Tomás Armuelles | E7: 878 | F7: 1 | G7: C&W Panamá | H7: 70
A8: Esc. Los Ángeles | B8: Chiriquí | C8: Barú | D8: Puerto Tomás Armuelles | E8: 1083 | F8: 1 | G8: C&W Panamá | H8: 71
A9: Esc. Márgenes de Corotú | B9: Chiriquí | C9: Barú | D9: Puerto Tomás Armuelles | E9: 3110 | F9: 1 | G9: C&W Panamá | H9: 72
A10: Esc. Sec. de Puerto Armuelles | B10: Chiriquí | C10: Barú | D10: Puerto Tomás Armuelles | E10: 3045 | F10: 1 | G10: C&W Panamá | H10: 74
A11: Esc. Tomás Armuelles | B11: Chiriquí | C11: Barú | D11: Puerto Tomás Armuelles | E11: 1707 | F11: 1 | G11: C&W Panamá | H11: 75
A12: Municipio Puerto Armuelles | B12: Chiriquí | C12: Barú | D12: Puerto Tomás Armuelles | E12: 2776 | F12: 1 | G12: C&W Panamá | H12: 77
A13: Parque Central Puerto Armuelles | B13: Chiriquí | C13: Barú | D13: Puerto Tomás Armuelles | E13: 3470 | F13: 1 | G13: C&W Panamá | H13: 78
... A61: Escuela Paso Canoas Arriba | B61: Chiriquí | C61: Barú | D61: Progreso | E61: 639 | F61: 1 | G61: C&W Panamá | H61: 1638

Sheet BD_DATA_TRANSFERIDA
A1: Nombre | B1: Provincia | C1: Distrito | D1: Corregimiento | E1: Total | F1: Región | G1: PA
A2: Esc. La Esperanza | B2: Chiriquí | C2: Barú | D2: Baco | E2: 74 | F2: 1 | G2: 64
A3: Esc. San Valentín | B3: Chiriquí | C3: Barú | D3: Baco | E3: 124 | F3: 1 | G3: 65
A4: Centro de Educ. Media de Progreso | B4: Chiriquí | C4: Barú | D4: Progreso | E4: 46 | F4: 1 | G4: 66
A5: Esc. Chuchupate | B5: Chiriquí | C5: Barú | D5: Progreso | E5: 191 | F5: 1 | G5: 68
A6: Biblioteca Pública Generosa Valdez de Diaz | B6: Chiriquí | C6: Barú | D6: Puerto Tomás Armuelles | E6: 48 | F6: 1 | G6: 69
A7: Bomberos Puerto Armuelles | B7: Chiriquí | C7: Barú | D7: Puerto Tomás Armuelles | E7: 49 | F7: 1 | G7: 70
A8: Esc. Los Ángeles | B8: Chiriquí | C8: Barú | D8: Puerto Tomás Armuelles | E8: 113 | F8: 1 | G8: 71
A9: Esc. Márgenes de Corotú | B9: Chiriquí | C9: Barú | D9: Puerto Tomás Armuelles | E9: 586 | F9: 1 | G9: 72
A10: Esc. Sec. de Puerto Armuelles | B10: Chiriquí | C10: Barú | D10: Puerto Tomás Armuelles | E10: 81 | F10: 1 | G10: 74
A11: Esc. Tomás Armuelles | B11: Chiriquí | C11: Barú | D11: Puerto Tomás Armuelles | E11: 188 | F11: 1 | G11: 75
A12: Municipio Puerto Armuelles | B12: Chiriquí | C12: Barú | D12: Puerto Tomás Armuelles | E12: 70 | F12: 1 | G12: 77
A13: Parque Central Puerto Armuelles | B13: Chiriquí | C13: Barú | D13: Puerto Tomás Armuelles | E13: 248 | F13: 1 | G13: 78
... A61: Escuela Paso Canoas Arriba | B61: Chiriquí | C61: Barú | D61: Progreso | E61: 89 | F61: 1 | G61: 1638

Sheet BD_MEDUCA
B1: MINISTERIO DE EDUCACIÓN
B2: OFICINA DE ESTADÍSTICA
B3: Actualizado: 19 de Junio de 2024
A4: Código SIACE | B4: Marco Muestral -Sistema Educativo | C4: Dependencia | D4: Estatus | E4: Provincia | F4: Región Escolar | G4: Distrito | H4: Corregimiento | I4: Nombre del Centro Educativo | J4: Área | K4: Indigena | L4: Áreas Comarcales | M4: Decretos (Creación, funcionamiento, cambio nombre, ampliación) | N4: Otros Decretos relacionados(Cambio de nombre, ampliacion, cierre) | O4: Oferta 2023 | P4: Bachiller
A5: 124 | B5: EDUCACIÓN INICIAL | C5: OFICIAL | D5: ACTIVA | E5: BOCAS DEL TORO | F5: BOCAS DEL TORO | G5: BOCAS DEL TORO | H5: BOCAS DEL TORO | I5: COIF ESTADO DE ISRAEL | J5: URBANA | K5: NO | L5: No | M5: NO ESPECIFICADO | O5: PREESCOLAR
A6: 16085 | B6: EDUCACIÓN INICIAL | C6: OFICIAL | D6: ACTIVA | E6: BOCAS DEL TORO | F6: BOCAS DEL TORO | G6: CHANGUINOLA | H6: CHANGUINOLA | I6: CAIPI MIS PRIMEROS PASOS DE TEOBROMA | J6: RURAL | K6: NO | L6: No | M6: NO ESPECIFICADO | O6: PREESCOLAR
A7: 226 | B7: EDUCACIÓN INICIAL-FORMAL | C7: OFICIAL | D7: ACTIVA | E7: BOCAS DEL TORO | F7: BOCAS DEL TORO | G7: CHANGUINOLA | H7: CHANGUINOLA | I7: COIF FROEBELIN | J7: URBANA | K7: NO | L7: No | M7: NO ESPECIFICADO | O7: PREESCOLAR
A8: 5566 | B8: SUBSISTEMA REGULAR | C8: OFICIAL | D8: ACTIVA | E8: BOCAS DEL TORO | F8: BOCAS DEL TORO | G8: CHANGUINOLA | H8: FINCA 30 | I8: ESC. BILINGÜE TEOBROMA | J8: URBANA | K8: NO | L8: No | M8: DEC. 446 DEL 14 DE AGOSTO DE 2018 INCORPORA LA DENOMINACION BILINGÜE AL NOMBRE | O8: PREESCOLAR-PRIMARIA
A9: 109 | B9: SUBSISTEMA REGULAR | C9: OFICIAL | D9: ACTIVA | E9: BOCAS DEL TORO | F9: BOCAS DEL TORO | G9: BOCAS DEL TORO | H9: TIERRA OSCURA | I9: ESC. AGUACATE | J9: INDIGENA | K9: SI | L9: No | M9: DEC. 468 DE 30 DE DICIEMBRE DE 1985 | O9: PRIMARIA
A10: 281 | B10: SUBSISTEMA REGULAR | C10: OFICIAL | D10: ACTIVA | E10: BOCAS DEL TORO | F10: BOCAS DEL TORO | G10: ALMIRANTE | H10: ALMIRANTE | I10: ESC. ALMIRANTE | J10: URBANA | K10: NO | L10: No | M10: DEC.18 DE 19 DE ABRIL DE 1915 | O10: PREESCOLAR-PRIMARIA
A11: 6351 | B11: SUBSISTEMA REGULAR | C11: OFICIAL | D11: ACTIVA | E11: BOCAS DEL TORO | F11: BOCAS DEL TORO | G11: ALMIRANTE | H11: CAUCHERO | I11: ESC. ALTO CAÑA | J11: INDIGENA | K11: SI | L11: No | M11: DEC. 230 DEL 11 DE JUNIO DE 2018. | O11: PRIMARIA
A12: 315 | B12: SUBSISTEMA REGULAR | C12: OFICIAL | D12: ACTIVA | E12: BOCAS DEL TORO | F12: BOCAS DEL TORO | G12: CHANGUINOLA | H12: LAS TABLAS | I12: ESC. ALTO DOS CAÑOS ANEXA | J12: INDIGENA | K12: SI | L12: No | M12: NO ESPECIFICADO | O12: PREESCOLAR-PRIMARIA
A13: 233 | B13: SUBSISTEMA REGULAR | C13: OFICIAL | D13: ACTIVA | E13: BOCAS DEL TORO | F13: BOCAS DEL TORO | G13: CHANGUINOLA | H13: COCHIGRO | I13: ESC. ALTO PITA | J13: INDIGENA | K13: SI | L13: No | M13: NO ESPECIFICADO | O13: PRIMARIA
A14: 5326 | B14: SUBSISTEMA REGULAR | C14: OFICIAL | D14: ACTIVA | E14: BOCAS DEL TORO | F14: BOCAS DEL TORO | G14: ALMIRANTE | H14: CAUCHERO | I14: ESC. ALTO REFUGIO | J14: INDIGENA | K14: SI | L14: No | M14: NO ESPECIFICADO | O14: PRIMARIA
A15: 5874 | B15: SUBSISTEMA REGULAR | C15: OFICIAL | D15: ACTIVA | E15: BOCAS DEL TORO | F15: BOCAS DEL TORO | G15: CHANGUINOLA | H15: COCHIGRO | I15: ESC. ALTO SORI | J15: INDIGENA | K15: SI | L15: No | M15: NO ESPECIFICADO | O15: PRIMARIA
A16: 125 | B16: SUBSISTEMA REGULAR | C16: OFICIAL | D16: ACTIVA | E16: BOCAS DEL TORO | F16: BOCAS DEL TORO | G16: ALMIRANTE | H16: CAUCHERO | I16: ESC. ARCELIO A. FITZGERAL | J16: INDIGENA | K16: SI | L16: No | M16: DEC.19 DE 11 DE ENERO DE 1968 | N16: El dect. 19 del 11 de enero de 1968 cambia el nombre de Escuela "CAUCHERO" por el de "Escuela Arcelio FitzGerald". Este decreto se puede ver | O16: PRIMARIA
A17: 101 | B17: SUBSISTEMA REGULAR | C17: OFICIAL | D17: ACTIVA | E17: BOCAS DEL TORO | F17: BOCAS DEL TORO | G17: BOCAS DEL TORO | H17: BASTIMENTO | I17: ESC. BAHIA HONDA | J17: RURAL | K17: NO | L17: No | M17: NO ESPECIFICADO | O17: PRIMARIA
A18: 375 | B18: SUBSISTEMA REGULAR | C18: OFICIAL | D18: ACTIVA | E18: BOCAS DEL TORO | F18: BOCAS DEL TORO | G18: CHIRIQUÍ GRANDE | H18: CHIRIQUÍ GRANDE | I18: ESC. BAHIA LA BALLENA | J18: INDIGENA | K18: SI | L18: No | M18: NO ESPECIFICADO | O18: PREESCOLAR-PRIMARIA-PREMEDIA
A19: 6350 | B19: SUBSISTEMA REGULAR | C19: OFICIAL | D19: ACTIVA | E19: BOCAS DEL TORO | F19: BOCAS DEL TORO | G19: BOCAS DEL TORO | H19: BASTIMENTO | I19: ESC. BAHIA ROJA | J19: INDIGENA | K19: SI | L19: No | M19: NO ESPECIFICADO | O19: PRIMARIA
A20: 343 | B20: SUBSISTEMA REGULAR | C20: OFICIAL | D20: ACTIVA | E20: BOCAS DEL TORO | F20: BOCAS DEL TORO | G20: CHANGUINOLA | H20: BARRANCO ADENTRO | I20: ESC. BARRANCO MEDIO | J20: INDIGENA | K20: SI | L20: No | M20: NO ESPECIFICADO | O20: PREESCOLAR-PRIMARIA
A21: 5563 | B21: SUBSISTEMA REGULAR | C21: OFICIAL | D21: ACTIVA | E21: BOCAS DEL TORO | F21: BOCAS DEL TORO | G21: ALMIRANTE | H21: BARRIADA GUAYMI | I21: ESC. BARRIADA GUAYMI | J21: URBANA | K21: NO | L21: No | M21: NO ESPECIFICADO | O21: PREESCOLAR-PRIMARIA
A22: 154 | B22: SUBSISTEMA REGULAR | C22: OFICIAL | D22: ACTIVA | E22: BOCAS DEL TORO | F22: BOCAS DEL TORO | G22: BOCAS DEL TORO | H22: BASTIMENTO | I22: ESC. BASTIMENTO | J22: RURAL | K22: NO | L22: No | M22: DEC.18 DE 19 DE ABRIL DE 1915 | O22: PREESCOLAR-PRIMARIA-PREMEDIA
A23: 312 | B23: SUBSISTEMA REGULAR | C23: OFICIAL | D23: ACTIVA | E23: BOCAS DEL TORO | F23: BOCAS DEL TORO | G23: CHANGUINOLA | H23: LAS DELICIAS | I23: ESC. BOCA DE YORKIN | J23: INDIGENA | K23: SI | L23: No | M23: DEC.415 DEL 23 DE AGOSTO DE 1963 | O23: PREESCOLAR-PRIMARIA
A24: 99 | B24: SUBSISTEMA REGULAR | C24: OFICIAL | D24: ACTIVA | E24: BOCAS DEL TORO | F24: BOCAS DEL TORO | G24: BOCAS DEL TORO | H24: BOCAS DEL TORO | I24: ESC. BOCA DE DRAGO | J24: RURAL | K24: NO | L24: No | M24: DEC.18 DE 19 DE ABRIL DE 1915 | N24: El dect. 18 de 19 de abril de 1915 crea la escuela Alternada de Boca del Drago | O24: PREESCOLAR-PRIMARIA
A25: 262 | B25: SUBSISTEMA REGULAR | C25: OFICIAL | D25: ACTIVA | E25: BOCAS DEL TORO | F25: BOCAS DEL TORO | G25: CHANGUINOLA | H25: CHANGUINOLA | I25: C.E.B.G. BILINGÜE CHANGUINOLA | J25: URBANA | K25: NO | L25: No | M25: DEC. 49 DE 13 DE JUNIO DE 1978 | N25: Decreto 446 del 14 de agosto de 2018 incorpora la denominacion Bilingüe al Nombre | O25: PREESCOLAR-PRIMARIA
A26: 478 | B26: SUBSISTEMA REGULAR | C26: OFICIAL | D26: ACTIVA | E26: BOCAS DEL TORO | F26: BOCAS DEL TORO | G26: CHIRIQUÍ GRANDE | H26: BAJO CEDRO | I26: C.E.B.G. BAJO CEDRO | J26: RURAL | K26: NO | L26: No | M26: DEC.107 DE 5 DE MAYO DE 1986 | N26: El dect. 107 de 5 de mayo de 1986 crea la escuela BAJO CEDRO. El dect. 614 del 3/8/2011 crea el centro educativo Bajo EL Cedro | O26: PREESCOLAR-PRIMARIA-PREMEDIA
A27: 338 | B27: SUBSISTEMA REGULAR | C27: OFICIAL | D27: ACTIVA | E27: BOCAS DEL TORO | F27: BOCAS DEL TORO | G27: CHANGUINOLA | H27: LAS TABLAS | I27: C.E.B.G. BILINGÜE NIEVECITA | J27: RURAL | K27: NO | L27: No | M27: DEC. 219 DE 27 DE JUNIO DE 2000 | N27: Dec. 122 del 3 de marzo del 2017 se crea la educacion media las nievecitas.Decreto 446 del 14 de agosto de 2018 incorpora la denominacion Bilingüe al Nombre | O27: PREESCOLAR-PRIMARIA-PREMEDIA
A28: 5320 | B28: SUBSISTEMA REGULAR | C28: OFICIAL | D28: ACTIVA | E28: BOCAS DEL TORO | F28: BOCAS DEL TORO | G28: CHANGUINOLA | H28: EL EMPALME | I28: C.E.B.G. BILINGÜE EL EMPALME | J28: URBANA | K28: NO | L28: No | M28: DEC. 446 DEL 14 DE AGOSTO DE 2018 INCORPORA LA DENOMINACION BILINGÜE AL NOMBRE | O28: PREESCOLAR-PRIMARIA-PREMEDIA
A29: 276 | B29: SUBSISTEMA REGULAR | C29: OFICIAL | D29: ACTIVA | E29: BOCAS DEL TORO | F29: BOCAS DEL TORO | G29: CHANGUINOLA | H29: FINCA 4 | I29: C.E.B.G. BILINGÜE FINCA 04 | J29: RURAL | K29: NO | L29: No | M29: DEC. DECT. 584 DEL 4 DE AGOSTO DE 2004 | N29: El dect. 76 de 9 de abril de 1954 da apertura a la escuela "FINCA CUATRO". El dect. 584 del 4 de agosto de 2004 crea el C. E.B.G. de Finca 4.Decreto 446 del 14 de agosto de 2018 incorpora la denominacion Bilingüe al Nombre | O29: PREESCOLAR-PRIMARIA-PREMEDIA
A30: 231 | B30: SUBSISTEMA REGULAR | C30: OFICIAL | D30: ACTIVA | E30: BOCAS DEL TORO | F30: BOCAS DEL TORO | G30: CHANGUINOLA | H30: FINCA 60 | I30: C.E.B.G. BILINGÜE FINCA 62 | J30: URBANA | K30: NO | L30: No | M30: DEC.34 DE 24 DE ENERO DE 1966 | N30: El dect. 168 de 8 de mayo de 1962 clausura la escuela FINCA 62. El dect. 34 de 24 de enero de 1966 ordena la reapertura de la escuela FINCA 62. El dect. 220 de 27 de junio de 2000 crea el Centro de Educación Básica General de Finca 62.Decreto 446 del 14 de agosto de 2018 incorpora la denominacion Bilingüe al Nombre | O30: PREESCOLAR-PRIMARIA-PREMEDIA
A31: 321 | B31: SUBSISTEMA REGULAR | C31: OFICIAL | D31: ACTIVA | E31: BOCAS DEL TORO | F31: BOCAS DEL TORO | G31: CHANGUINOLA | H31: LA MESA | I31: C.E.B.G. BILINGÜE MARIANO THOMAS | J31: RURAL | K31: NO | L31: No | M31: DEC.70 DE 21 DE MARZO DE 1972 | N31: El dect. 70 de 21 de marzo de 1972 crea la escuela La Mesa. El dect. 128 del 24 de julio de 1997 asigna el nombre de Mariano Thomas a la Escuela La Mesa | O31: PREESCOLAR-PRIMARIA-PREMEDIA
A32: 288 | B32: SUBSISTEMA REGULAR | C32: OFICIAL | D32: ACTIVA | E32: BOCAS DEL TORO | F32: BOCAS DEL TORO | G32: ALMIRANTE | H32: VALLE DEL RISCÓ | I32: C.E.B.G. BILINGÜE VALLE DE RISCO | J32: RURAL | K32: NO | L32: No | M32: DEC.110 DE 4 DE ABRIL DE 1966. DEC. 739 DEL 19 DE NOV. DE 2018 QUE DEROGA EN TODAS SUS PARTES EL DEC. EJECUTIVO NO. 1074 DEL 16 DE DIC. DE 2016 Y SE EMPLEMENTA EL SEGUNDO NIVEL DE ENSEÑANZA O EDUCACION MEDIA. | N32: El dect. 110 de 4 de abril de 1966 crea la escuela Valle de Risco. El dect. 181 de 24 de octubre de 1997 crea el Primer Ciclo Valle del Risco | O32: PREESCOLAR-PRIMARIA-PREMEDIA-MEDIA ACADÉMICA-MEDIA PROFESIONAL Y TÉCNICA | P32: CIENCIAS, TECNOLOGIA E INFORMATICA
A33: 267 | B33: SUBSISTEMA REGULAR | C33: OFICIAL | D33: ACTIVA | E33: BOCAS DEL TORO | F33: BOCAS DEL TORO | G33: CHANGUINOLA | H33: LA GLORIA | I33: C.E.B.G. LA GLORIA | J33: RURAL | K33: NO | L33: No | M33: DEC.20 DE 31 DE ENERO DE 1972 | O33: PREESCOLAR-PRIMARIA-PREMEDIA
A34: 307 | B34: SUBSISTEMA REGULAR | C34: OFICIAL | D34: ACTIVA | E34: BOCAS DEL TORO | F34: BOCAS DEL TORO | G34: ALMIRANTE | H34: NANCE DE RISCO | I34: C.E.B.G. NANCE DE RISCO | J34: INDIGENA | K34: SI | L34: No | M34: DEC.20 DE 31 DE ENERO DE 1972 | N34: El dect. 20 de 31 de enero de 1972 crea la escuela Nance de Risco. El dect. 614 del 3/8/2011 crea el centro educativo Nance de Risco | O34: PREESCOLAR-PRIMARIA-PREMEDIA
A35: 396 | B35: SUBSISTEMA REGULAR | C35: OFICIAL | D35: ACTIVA | E35: BOCAS DEL TORO | F35: BOCAS DEL TORO | G35: CHIRIQUÍ GRANDE | H35: PUNTA PEÑA | I35: C.E.B.G. PUNTA PEÑA | J35: RURAL | K35: NO | L35: No | M35: DEC. 166 DEL 11 DE MAYO DE 1960 | O35: PREESCOLAR-PRIMARIA-PREMEDIA
A36: 5323 | B36: SUBSISTEMA REGULAR | C36: OFICIAL | D36: ACTIVA | E36: BOCAS DEL TORO | F36: BOCAS DEL TORO | G36: ALMIRANTE | H36: VALLE DE AGUAS ARRIBA | I36: C.E.B.G. QUEBRADA PASTOR | J36: INDIGENA | K36: SI | L36: No | M36: DEC.70 DE 21 DE MARZO DE 1972 | N36: El dect. 70 de 21 de marzo de 1972 crea la escuela Quebrada Pastor, en el corregimiento de Valle Riscó. El dect. 581 de 4 de agosto de 2004 crea el C.E.B.G. Quebrada Pastor | O36: PREESCOLAR-PRIMARIA-PREMEDIA
A37: 5324 | B37: SUBSISTEMA REGULAR | C37: OFICIAL | D37: ACTIVA | E37: BOCAS DEL TORO | F37: BOCAS DEL TORO | G37: CHANGUINOLA | H37: EL TERIBE | I37: C.E.B.G. SIEYICK | J37: INDIGENA | K37: SI | L37: NASO | M37: NO ESPECIFICADO | O37: PREESCOLAR-PRIMARIA-PREMEDIA | P37: TURISMO
A38: 339 | B38: SUBSISTEMA REGULAR | C38: OFICIAL | D38: ACTIVA | E38: BOCAS DEL TORO | F38: BOCAS DEL TORO | G38: CHANGUINOLA | H38: GUABITO | I38: C.E.B.G. BILINGÜE GUABITO | J38: RURAL | K38: NO | L38: No | M38: DEC. 49 DE 13 DE JUNIO DE 1978 | N38: Decreto 446 del 14 de agosto de 2018 incorpora la denominacion Bilingüe al Nombre | O38: PREESCOLAR-PRIMARIA-PREMEDIA
A39: 374 | B39: SUBSISTEMA REGULAR | C39: OFICIAL | D39: ACTIVA | E39: BOCAS DEL TORO | F39: BOCAS DEL TORO | G39: CHANGUINOLA | H39: COCHIGRO | I39: ESC. CABLE VIA | J39: INDIGENA | K39: SI | L39: No | M39: NO ESPECIFICADO | O39: PRIMARIA
A40: 127 | B40: SUBSISTEMA REGULAR | C40: OFICIAL | D40: ACTIVA | E40: BOCAS DEL TORO | F40: BOCAS DEL TORO | G40: BOCAS DEL TORO | H40: BOCAS DEL TORO | I40: ESC. CARENERO | J40: RURAL | K40: NO | L40: No | M40: DEC.101 DE 7 DE ABRIL DE 1961 | O40: PREESCOLAR-PRIMARIA
...
